Workbook

Sheet README
A1: Calyx Containers — Flex Sourcing Program Tracker
A2: Working companion to the Flexible Packaging Sourcing Program Playbook. Kickoff: Week of Mon Jun 29, 2026. North star: 50 factories.
A5: Tab | B5: What it's for
A6: Roadmap | B6: Wave/phase roadmap (Wave 1 → Wave 2 → Flexo/Roto → Tins → Pop-top tubes → Boxes), dated.
A7: Weekly Timeline | B7: Week-by-week goals for both tracks (Weeks 1-12), cumulative contracted, gates.
A8: Supplier Pipeline Tracker | B8: MASTER vendor list. One row per candidate. Pre-loaded with the Week-0 warm pipeline.
A9: Sprint Scorecard | B9: Per-sprint + cumulative KPIs. Auto-computed from the Pipeline Tracker (no manual tallying).
A10: Contract & Document Status | B10: Per-vendor contract paper status (NDA/MSA/annex), Calyx-legal-name check, IP/non-compete.
A11: Risk Register | B11: Program risks, likelihood/impact, mitigation, owner.
A12: Reference Lists | B12: Dropdown source values (Track, Tier, Stage, Category, etc.). Edit here to change dropdowns.
A14: Key rule | B14: A vendor is CONTRACTED when it has an MSA_Date AND Capability_Verified = "Y" (real manufacturer, not a broker). Trial / PSI / AQL run on the follow-on qualification track and do NOT block the contract gate.
A15: Stages | B15: Identify → Screen → Qualify → NDA → RFQ → Sample → Tour/Audit → Contracted → Qualifying → Active (or Parked).
A16: Tiers | B16: T1 = primary · T2 = backup · T3 = pipeline.
A17: Legend | B17: Status RAG: Green = on track · Amber = at risk · Red = blocked. Amber fill = sourcing gap / needs verification.

Sheet Roadmap
A1: Wave & Phase Roadmap
A2: Flex first; later phases telescope. Identification leads contracting by one sprint; qualification trails it.
A4: Wave / Phase | B4: Scope | C4: Domestic (Jake) | D4: International (Steven +2) | E4: Sprint / Weeks | F4: Exit gate
A5: Wave 1 — Digital flex (beachhead) | B5: Domestic digital mid-web ("Spaceship") + intl digital flex; pair w/ labels | C5: 2 → NDA+MSA+capability | D5: 1 → NDA/MSA + factory tour | E5: Sprint 1 / Wks 1-2 | F5: 3 contracted; intl tour done; qual track opened; PackOS fields live
A6: Wave 2 — Flex scale ("quick second") | B6: More flexpack (digital + early flexo-capable) | C6: +3 | D6: +3 Guangdong (incl. >=1 Vietnam) | E6: Sprint 2 / Wks 3-4 | F6: Cum. 9; all tier-tagged; Wave 1 trials/PSI in motion
A7: Phase 3 — Flexo / Rotogravure | B7: High-volume flexo + roto, both tracks | C7: +2-3 | D7: +2-3 (Guangdong + East China) | E7: Sprints 3-4 / Wks 5-8 | F7: Cum. ~15; Wave 1 go/no-go; first T1 promotion; ~30% to 50
A8: Phase 4 — Tin containers | B8: Tins (mine CNY-list tin vendors) | C8: +2 | D8: +2-3 | E8: Sprints 5-6 / Wks 9-12 | F8: Cum. ~19-20; dual-country live >=1 category
A9: Phase 5 — Pop-top tubes | B9: Pre-labeled pop tubes (#1 new intl request) | C9: support | D9: +3 (pre-label capable) | E9: Sprints 6-7 / Wks 11-14 | F9: Pre-label pop-tube trial; label+tube spec in PackOS
A10: Phase 6 — Boxes (Rigid/CR + SBS/Display) | B10: Rigid/CR + SBS/display | C10: +2 | D10: +2-3 (East China + Vietnam paper offset) | E10: Sprints 7-9 / Wks 13-18 | F10: Cum. ~28-30+; Phase 2 Scale ($500K->$2M) underway

Sheet Weekly Timeline
A1: Weekly Goal Timeline (Weeks 0-12)
A2: Kickoff Mon Jun 29, 2026. Holidays: Fri Jul 3 (sign by Thu Jul 2); Mon Sep 7 Labor Day (move sync to Tue Sep 8).
A4: Wk | B4: Dates | C4: Domestic (Jake) | D4: International (Steven +2) | E4: Cum. contracted | F4: Gate / milestone
A5: 0 | B5: Jun 22-26 | C5: Build warm pipeline; templates/signature/Legal SLA; open PackOS fields; deposit envelope | D5: Same — warm Guangdong list + CNY-vendor outreach | E5: 0 | F5: Pre-work complete
A6: 1 | B6: Jun 29-Jul 3 | C6: Down-select 2 digital mid-web; RFIs/NDAs out; samples requested | D6: NDA out; factory tour executed; MSA issued | E6: 0 | F6: Sprint 1 midpoint
A7: 2 | B7: Jul 6-10 | C7: 2 domestic NDA+MSA + capability verified | D7: 1 intl NDA/MSA + tour + capability verified | E7: 3 | F7: * Wave 1 contracted; first Supply Web entries
A8: 3 | B8: Jul 13-17 | C8: Down-select 3 dom flexpack; RFQs out | D8: 3 Guangdong (incl. >=1 Vietnam) NDAs/tours scheduled | E8: 3 | F8: Sprint 2 start; Wave 1 trials in transit
A9: 4 | B9: Jul 20-24 | C9: +3 domestic contracted | D9: +3 intl contracted + tours | E9: 9 | F9: * Wave 2 contracted (+3/+3); roto sourcing begins
A10: 5 | B10: Jul 27-31 | C10: Identify dom flexo/roto; Wave-1 samples approved | D10: Flexo/roto NDAs; tours; Wave-1 samples arrive | E10: 9 | F10: Sprint 3 start
A11: 6 | B11: Aug 3-7 | C11: +1-2 dom flexo; Wave-1 dom -> T1 | D11: +1-2 intl flexo; tours done | E11: ~12 | F11: Wave 1 intl PSI result in
A12: 7 | B12: Aug 10-14 | C12: Roto contracting; manage trials | D12: +1 intl roto; Wave-1 first shipment clears (ISF 10+2) | E12: ~13 | F12: * Wave 1 intl go/no-go
A13: 8 | B13: Aug 17-21 | C13: +2-3 dom flexo/roto total | D13: +2-3 intl flexo/roto total | E13: ~15 | F13: * Phase 3 contracted; Month-2 checkpoint; ~30% to 50
A14: 9 | B14: Aug 24-28 | C14: Identify dom tin | D14: Intl tin NDAs (CNY-list); Vietnam activated | E14: ~15 | F14: Dual-country live
A15: 10 | B15: Aug 31-Sep 4 | C15: +2 dom tin | D15: +2 intl tin; tours | E15: ~19 | F15: Nearing Yr-1 "20 certified"
... A17: 12 | B17: Sep 14-18 | C17: Identify dom boxes | D17: +2 intl pop-tube; box sourcing begins | E17: ~22-23 | F17: * End-of-POC (Month 3) go/no-go; ~45% to 50

Sheet Supplier Pipeline Tracker
B1: Supplier Pipeline Tracker (master)
B2: One row per candidate vendor. CONTRACTED = MSA_Date filled AND Capability_Verified = "Y". Pre-loaded with the Week-0 warm pipeline.
B4: Vendor_ID | C4: Digital /Flexo / Roto | D4: Vendor_Name | E4: Status | F4: Website | G4: Track | H4: Country | I4: Cluster | J4: Category | K4: Sub_Capability | L4: Tier | M4: Primary/Secondary | N4: Stage | O4: Owner | P4: Wave Sprint | Q4: NDA Date | R4: MSA Date | S4: Capability Verified | T4: Factory Tour Date | U4: RFQ Sent | V4: Quote Received | W4: Quoted Price | X4: Target Price | Y4: Price vs Target % | Z4: MOQ | AA4: Deposit % | AB4: Lead_Time_Days | AC4: AQL_Standard | AD4: PSI_Status | AE4: Trial_Order_No | AF4: Trial_Result | AG4: Command_Integrated | AH4: PackOS_Handoff | AI4: IP_Clause | AJ4: NonCompete_24mo | AK4: Status_RAG | AL4: Next_Action | AM4: Next_Action_Due
A5: 1 | B5: FLEX-D-001 | C5: Flexographic | D5: DazPak Flexible Packaging | E5: Active | G5: Domestic | H5: USA | I5: US-CA | J5: Domestic Flexographic | K5: Pouches/rollstock, low MOQ | L5: T1 | M5: Primary | N5: Qualify | O5: Jake King | P5: S1 | Y5: =IF(OR(W5="",X5=""),"",(X5-W5)/X5)
A6: 1 | B6: FLEX-D-002 | C6: Digital | D6: Ross Print & Packaging | E6: Active | G6: Domestic | H6: USA | I6: US-WA | J6: Domestic Digital | K6: HP Indigo + flexo + labels | L6: T2 | M6: Secondary | N6: Qualify | O6: Jake King | P6: S1 | Y6: =IF(OR(W6="",X6=""),"",(X6-W6)/X6)
A7: 1 | B7: FLEX-D-004 | C7: Flexographic | D7: Morris Packaging | E7: Active | G7: Domestic | H7: USA | I7: US-IL | J7: Domestic Flexographic | K7: Pouches/roll stock, sustainable films | L7: T2 | M7: Secondary | N7: Identify | O7: Jake King | P7: S2 | Y7: =IF(OR(W7="",X7=""),"",(X7-W7)/X7)
A8: 1 | B8: FLEX-D-005 | C8: Digital | D8: InkWorks Printing | E8: Active | G8: Domestic | H8: USA | I8: US-WI | J8: Domestic Digital | K8: PS labels, pouch/mailer print | L8: T3 | M8: Secondary | N8: Identify | O8: Jake King | P8: S2 | Y8: =IF(OR(W8="",X8=""),"",(X8-W8)/X8)
A9: 1 | B9: FLEX-D-007 | C9: Rotogravure | D9: Takigawa Corp. America | E9: Active | G9: Domestic | H9: USA | I9: US-KY | J9: Domestic Rotogravure | K9: High-barrier pouches/rollstock | L9: T1 | M9: Primary | N9: Identify | O9: Jake King | P9: S3 | Y9: =IF(OR(W9="",X9=""),"",(X9-W9)/X9)
A10: 1 | B10: FLEX-I-002 | C10: Rotogravure | D10: TedPack Company Ltd. | E10: Active | G10: International | H10: China | I10: Guangdong | J10: International Rotogravure | K10: Custom pouches; ISO/BRCGS/BSCI | L10: T1 | M10: Primary | N10: Identify | O10: Steven Yao | P10: S2 | Y10: =IF(OR(W10="",X10=""),"",(X10-W10)/X10)
A11: 1 | B11: FLEX-D-003 | C11: Digital | D11: Lauterbach Group | E11: Not Contacted | F11: https://www.lauterbachgroup.com/ | G11: Domestic | H11: USA | I11: US-WI | J11: Domestic Digital | Y11: =IF(OR(W11="",X11=""),"",(X11-W11)/X11)
A12: 1 | B12: FLEX-D-006 | C12: Digital | D12: Brand my Bags | E12: In Process | F12: https://brandmybags.com/ | G12: Domestic | H12: USA | I12: US-WI | J12: Domestic Digital | O12: Jake King | P12: S1 | Q12: 46197
A13: 1 | B13: FLEX-D-008 | C13: Digital | D13: Impackt | E13: In Process | G13: Domestic | H13: USA | I13: US-CA | J13: Domestic Digital | O13: Jake King | P13: S1
A14: 1 | B14: FLEX-D-009 | C14: Digital | D14: The Pouch House | E14: Not Contacted | F14: https://www.thepouchhouse.com/ | G14: Domestic | H14: USA | I14: US-MN | J14: Domestic Digital | Y14: =IF(OR(W14="",X14=""),"",(X14-W14)/X14)
A15: 1 | B15: FLEX-I-001 | C15: Rotogravure | D15: Dongguan Xueliang Packaging | E15: Not Contacted | F15: http://dgbpack.com/Cases.html | G15: International | H15: China | I15: Guangdong | J15: International Digital | K15: CR Pouch — verify digital print | L15: T3 | M15: Secondary | N15: Identify | O15: Steven Yao | P15: S1 | Y15: =IF(OR(W15="",X15=""),"",(X15-W15)/X15)
A16: 1 | B16: FLEX-I-003 | C16: Digital / Rotogravure | D16: BowePack (Guangdong Bowe Packaging) | E16: Not Contacted | F16: https://bowepack.com/ | G16: International | H16: China | I16: Yunfu City, Guangdong | Y16: =IF(OR(W16="",X16=""),"",(X16-W16)/X16)
A17: 1 | B17: FLEX-I-004 | C17: Rotogravure | D17: Wellfapack (Shantou Wellfa) | E17: Not Contacted | F17: https://wellfapack.com/about-shantou-wellfa-print-pack-co-ltd/ | G17: International | H17: China | I17: Shantou, Guangdong | Y17: =IF(OR(W17="",X17=""),"",(X17-W17)/X17)
A18: 1 | B18: FLEX-I-005 | C18: Digital / Rotogravure | D18: Gozen Packaging | E18: Not Contacted | F18: https://www.gozenpackaging.com/pcr-packaging-bags/ | G18: International | H18: China | Y18: =IF(OR(W18="",X18=""),"",(X18-W18)/X18)
A19: 1 | B19: FLEX-I-006 | C19: Rotogravure | D19: Qiyu Pack | E19: Not Contacted | F19: https://qiyupack.com/ | G19: International | H19: China | Y19: =IF(OR(W19="",X19=""),"",(X19-W19)/X19)
A20: 1 | B20: FLEX-I-007 | C20: Rotogravure | D20: Saigon Trapaco | E20: Not Contacted | F20: https://saigontrapaco.com.vn/vi/index.html | G20: International | H20: Vietnam | I20: Ho Chi Minh City area | Y20: =IF(OR(W20="",X20=""),"",(X20-W20)/X20)
A21: 1 | B21: FLEX-I-008 | C21: Rotogravure | D21: Ngai Mee Packaging Vietnam | E21: Not Contacted | F21: https://ngaimee.com/ | G21: International | H21: Vietnam | Y21: =IF(OR(W21="",X21=""),"",(X21-W21)/X21)
A22: 1 | B22: FLEX-I-009 | C22: Rotogravure | D22: Amiba | E22: Not Contacted | F22: https://amibapack.com/en/product/tui-dung-2/ | G22: International | H22: Vietnam | Y22: =IF(OR(W22="",X22=""),"",(X22-W22)/X22)
A23: 1 | B23: FLEX-I-010 | C23: Rotogravure | D23: SIVICO JSC | E23: Not Contacted | F23: https://www.sivico.com.vn/en/contact.html | G23: International | H23: Vietnam | I23: Hai Phong | Y23: =IF(OR(W23="",X23=""),"",(X23-W23)/X23)
A24: 1 | B24: FLEX-I-011 | C24: Digital | D24: ASUWANT PACKAGING | E24: In Process | F24: https://www.asuwantpackaging.com/ | G24: International | H24: China | I24: Jiang Men | J24: International Digital | K24: International Rotogravure + Paper Box
A25: 2 | B25: TUBE-I-001 | D25: Yiwu Sucheng Packaging | E25: Not Contacted | G25: International | H25: China | I25: East China | J25: Pop-top Tubes | K25: Pop Top Tube | L25: T2 | M25: Primary | N25: Identify | O25: Steven Yao | P25: S6 | Y25: =IF(OR(W25="",X25=""),"",(X25-W25)/X25)
A26: 2 | B26: TUBE-I-002 | D26: Mitsuiwa Shinko (MTS) | E26: Not Contacted | G26: International | H26: Taiwan | I26: Taiwan | J26: Pop-top Tubes | K26: Paper tube, paper box | L26: T3 | M26: Secondary | N26: Identify | O26: Steven Yao | P26: S6 | Y26: =IF(OR(W26="",X26=""),"",(X26-W26)/X26)
A27: 2 | B27: TUBE-I-003 | C27: Maybe Broker? | D27: ZAAM INTERNATIONAL CO., LTD | E27: Not Contacted | G27: International | H27: Vietnam | Y27: =IF(OR(W27="",X27=""),"",(X27-W27)/X27)
A28: 2 | B28: TUBE-I-004 | D28: JK Packaging | E28: Not Contacted | F28: https://jk-packaging.com/ | G28: International | H28: China | Y28: =IF(OR(W28="",X28=""),"",(X28-W28)/X28)
A29: 2 | B29: TUBE-I-005 | D29: Dewei Plastics | E29: Not Contacted | F29: https://www.dwplastic.com/ | G29: International | H29: China | Y29: =IF(OR(W29="",X29=""),"",(X29-W29)/X29)
A30: 3 | B30: TIN-I-001 | D30: TinWonder (Dongguan) | E30: Early Conversations | G30: International | H30: China | I30: Guangdong | J30: Tins | K30: Tinplate boxes & cans, 2,000+ molds | L30: T1 | M30: Primary | N30: Identify | O30: Steven Yao | P30: S5 | Y30: =IF(OR(W30="",X30=""),"",(X30-W30)/X30)
A31: 3 | B31: TIN-I-002 | D31: Andylots Tin Box | E31: Early Conversations | G31: International | H31: China | I31: Guangdong | J31: Tins | K31: CR tins for cannabis | L31: T1 | M31: Primary | N31: Identify | O31: Steven Yao | P31: S5 | Y31: =IF(OR(W31="",X31=""),"",(X31-W31)/X31)
A32: 3 | B32: TIN-I-003 | D32: Dongguan Lianglvfang | E32: Not Contacted | G32: International | H32: China | I32: Guangdong | J32: Tins | K32: Tin CR/Non-CR, Slide Tin CR | L32: T2 | M32: Secondary | N32: Identify | O32: Steven Yao | P32: S5 | Y32: =IF(OR(W32="",X32=""),"",(X32-W32)/X32)
A33: 3 | B33: TIN-I-004 | D33: Dongguan Xinyu Tin Can | E33: Not Contacted | G33: International | H33: China | I33: Guangdong | J33: Tins | K33: Tin | L33: T3 | M33: Secondary | N33: Identify | O33: Steven Yao | P33: S5 | Y33: =IF(OR(W33="",X33=""),"",(X33-W33)/X33)
A34: 3 | B34: TIN-I-005 | D34: Foshan Yuelida Metal Cap | E34: Not Contacted | G34: International | H34: China | I34: Guangdong | J34: Tins | K34: Tin | L34: T3 | M34: Secondary | N34: Identify | O34: Steven Yao | P34: S6 | Y34: =IF(OR(W34="",X34=""),"",(X34-W34)/X34)
A35: 3 | B35: TIN-I-006 | D35: Paulin Vina | E35: Not Contacted | G35: International | H35: Vietnam | I35: Vietnam | J35: Tins | K35: Tin (Vietnam tariff hedge) | L35: T2 | M35: Secondary | N35: Identify | O35: Steven Yao | P35: S6 | Y35: =IF(OR(W35="",X35=""),"",(X35-W35)/X35)
A36: 4 | B36: BOX-D-001 | D36: California Packaging & Display | E36: Different Scope/ Not Contacted | G36: Domestic | H36: USA | I36: US-CA | J36: Boxes (SBS/Display) | K36: Folding cartons, POP displays | L36: T1 | M36: Primary | N36: Identify | O36: Jake King | P36: S7 | Y36: =IF(OR(W36="",X36=""),"",(X36-W36)/X36)
A37: 4 | B37: BOX-D-002 | D37: Virtual Packaging | E37: Active | G37: Domestic | H37: USA | I37: US-TX | J37: Boxes (Rigid/CR) | K37: Rigid boxes, CR, prototyping | L37: T2 | M37: Secondary | N37: Identify | O37: Jake King | P37: S7 | Y37: =IF(OR(W37="",X37=""),"",(X37-W37)/X37)
A38: 4 | B38: BOX-I-001 | D38: Dongguan Fuyang Printing | E38: Not Contacted | G38: International | H38: China | I38: Guangdong | J38: Boxes (Rigid/CR) | K38: Paper/CR/Rigid/Magnetic box | L38: T2 | M38: Primary | N38: Identify | O38: Steven Yao | P38: S7 | Y38: =IF(OR(W38="",X38=""),"",(X38-W38)/X38)
A39: 4 | B39: BOX-I-002 | D39: TaPuMei Printing | E39: Not Contacted | G39: International | H39: China | I39: Guangdong | J39: Boxes (Rigid/CR) | K39: CR/Set-up/Flat/Magnetic box | L39: T2 | M39: Secondary | N39: Identify | O39: Steven Yao | P39: S7 | Y39: =IF(OR(W39="",X39=""),"",(X39-W39)/X39)
A40: 4 | B40: BOX-I-003 | D40: Intramedia Dongguan | E40: Not Contacted | G40: International | H40: China | I40: Guangdong | J40: Boxes (Rigid/CR) | K40: CR/Flat/Setup box | L40: T3 | M40: Secondary | N40: Identify | O40: Steven Yao | P40: S7 | Y40: =IF(OR(W40="",X40=""),"",(X40-W40)/X40)
A41: 4 | B41: BOX-I-004 | D41: Intramedia Minh Duc | E41: Not Contacted | G41: International | H41: Vietnam | I41: Vietnam | J41: Boxes (SBS/Display) | K41: Paper box (Vietnam) | L41: T3 | M41: Secondary | N41: Identify | O41: Steven Yao | P41: S7 | Y41: =IF(OR(W41="",X41=""),"",(X41-W41)/X41)
...

Sheet Sprint Scorecard
A1: Sprint Scorecard
A2: Auto-computed from the Supplier Pipeline Tracker. Wave_Sprint values (S1..S9) drive the per-sprint counts. Target = 50 factories.
A4: Sprint | B4: Weeks | C4: Dates | D4: Target_Contracted | E4: Actual_Contracted | F4: NDAs_Executed | G4: MSAs_Executed | H4: Tours_Completed | I4: Capability_Verified | J4: Trial_Orders_Placed | K4: Cumulative_Contracted | L4: %_to_Target_50 | M4: RAG | N4: Commentary
A5: S1 | B5: Wks 1-2 | C5: Jun 29 - Jul 10 | D5: 3 | E5: =COUNTIFS('Supplier Pipeline Tracker'!$P:$P,$A5,'Supplier Pipeline Tracker'!$R:$R,"<>",'Supplier Pipeline Tracker'!$S:$S,"Y") -> 0 | F5: =COUNTIFS('Supplier Pipeline Tracker'!$P:$P,$A5,'Supplier Pipeline Tracker'!$Q:$Q,"<>") -> 1 | G5: =COUNTIFS('Supplier Pipeline Tracker'!$P:$P,$A5,'Supplier Pipeline Tracker'!$R:$R,"<>") -> 0 | H5: =COUNTIFS('Supplier Pipeline Tracker'!$P:$P,$A5,'Supplier Pipeline Tracker'!$T:$T,"<>") -> 0 | I5: =COUNTIFS('Supplier Pipeline Tracker'!$P:$P,$A5,'Supplier Pipeline Tracker'!$S:$S,"Y") -> 0 | J5: =COUNTIFS('Supplier Pipeline Tracker'!$P:$P,$A5,'Supplier Pipeline Tracker'!$AE:$AE,"<>") -> 0 | K5: =SUM($E$5:$E5) -> 0 | L5: =$K5/50 -> 0 | M5: Green
A6: S2 | B6: Wks 3-4 | C6: Jul 13 - Jul 24 | D6: 6 | E6: =COUNTIFS('Supplier Pipeline Tracker'!$P:$P,$A6,'Supplier Pipeline Tracker'!$R:$R,"<>",'Supplier Pipeline Tracker'!$S:$S,"Y") -> 0 | F6: =COUNTIFS('Supplier Pipeline Tracker'!$P:$P,$A6,'Supplier Pipeline Tracker'!$Q:$Q,"<>") -> 0 | G6: =COUNTIFS('Supplier Pipeline Tracker'!$P:$P,$A6,'Supplier Pipeline Tracker'!$R:$R,"<>") -> 0 | H6: =COUNTIFS('Supplier Pipeline Tracker'!$P:$P,$A6,'Supplier Pipeline Tracker'!$T:$T,"<>") -> 0 | I6: =COUNTIFS('Supplier Pipeline Tracker'!$P:$P,$A6,'Supplier Pipeline Tracker'!$S:$S,"Y") -> 0 | J6: =COUNTIFS('Supplier Pipeline Tracker'!$P:$P,$A6,'Supplier Pipeline Tracker'!$AE:$AE,"<>") -> 0 | K6: =SUM($E$5:$E6) -> 0 | L6: =$K6/50 -> 0 | M6: Green
A7: S3 | B7: Wks 5-6 | C7: Jul 27 - Aug 7 | D7: 3 | E7: =COUNTIFS('Supplier Pipeline Tracker'!$P:$P,$A7,'Supplier Pipeline Tracker'!$R:$R,"<>",'Supplier Pipeline Tracker'!$S:$S,"Y") -> 0 | F7: =COUNTIFS('Supplier Pipeline Tracker'!$P:$P,$A7,'Supplier Pipeline Tracker'!$Q:$Q,"<>") -> 0 | G7: =COUNTIFS('Supplier Pipeline Tracker'!$P:$P,$A7,'Supplier Pipeline Tracker'!$R:$R,"<>") -> 0 | H7: =COUNTIFS('Supplier Pipeline Tracker'!$P:$P,$A7,'Supplier Pipeline Tracker'!$T:$T,"<>") -> 0 | I7: =COUNTIFS('Supplier Pipeline Tracker'!$P:$P,$A7,'Supplier Pipeline Tracker'!$S:$S,"Y") -> 0 | J7: =COUNTIFS('Supplier Pipeline Tracker'!$P:$P,$A7,'Supplier Pipeline Tracker'!$AE:$AE,"<>") -> 0 | K7: =SUM($E$5:$E7) -> 0 | L7: =$K7/50 -> 0 | M7: Green
A8: S4 | B8: Wks 7-8 | C8: Aug 10 - Aug 21 | D8: 3 | E8: =COUNTIFS('Supplier Pipeline Tracker'!$P:$P,$A8,'Supplier Pipeline Tracker'!$R:$R,"<>",'Supplier Pipeline Tracker'!$S:$S,"Y") -> 0 | F8: =COUNTIFS('Supplier Pipeline Tracker'!$P:$P,$A8,'Supplier Pipeline Tracker'!$Q:$Q,"<>") -> 0 | G8: =COUNTIFS('Supplier Pipeline Tracker'!$P:$P,$A8,'Supplier Pipeline Tracker'!$R:$R,"<>") -> 0 | H8: =COUNTIFS('Supplier Pipeline Tracker'!$P:$P,$A8,'Supplier Pipeline Tracker'!$T:$T,"<>") -> 0 | I8: =COUNTIFS('Supplier Pipeline Tracker'!$P:$P,$A8,'Supplier Pipeline Tracker'!$S:$S,"Y") -> 0 | J8: =COUNTIFS('Supplier Pipeline Tracker'!$P:$P,$A8,'Supplier Pipeline Tracker'!$AE:$AE,"<>") -> 0 | K8: =SUM($E$5:$E8) -> 0 | L8: =$K8/50 -> 0 | M8: Green
A9: S5 | B9: Wks 9-10 | C9: Aug 24 - Sep 4 | D9: 4 | E9: =COUNTIFS('Supplier Pipeline Tracker'!$P:$P,$A9,'Supplier Pipeline Tracker'!$R:$R,"<>",'Supplier Pipeline Tracker'!$S:$S,"Y") -> 0 | F9: =COUNTIFS('Supplier Pipeline Tracker'!$P:$P,$A9,'Supplier Pipeline Tracker'!$Q:$Q,"<>") -> 0 | G9: =COUNTIFS('Supplier Pipeline Tracker'!$P:$P,$A9,'Supplier Pipeline Tracker'!$R:$R,"<>") -> 0 | H9: =COUNTIFS('Supplier Pipeline Tracker'!$P:$P,$A9,'Supplier Pipeline Tracker'!$T:$T,"<>") -> 0 | I9: =COUNTIFS('Supplier Pipeline Tracker'!$P:$P,$A9,'Supplier Pipeline Tracker'!$S:$S,"Y") -> 0 | J9: =COUNTIFS('Supplier Pipeline Tracker'!$P:$P,$A9,'Supplier Pipeline Tracker'!$AE:$AE,"<>") -> 0 | K9: =SUM($E$5:$E9) -> 0 | L9: =$K9/50 -> 0 | M9: Green
A10: S6 | B10: Wks 11-12 | C10: Sep 7 - Sep 18 | D10: 3 | E10: =COUNTIFS('Supplier Pipeline Tracker'!$P:$P,$A10,'Supplier Pipeline Tracker'!$R:$R,"<>",'Supplier Pipeline Tracker'!$S:$S,"Y") -> 0 | F10: =COUNTIFS('Supplier Pipeline Tracker'!$P:$P,$A10,'Supplier Pipeline Tracker'!$Q:$Q,"<>") -> 0 | G10: =COUNTIFS('Supplier Pipeline Tracker'!$P:$P,$A10,'Supplier Pipeline Tracker'!$R:$R,"<>") -> 0 | H10: =COUNTIFS('Supplier Pipeline Tracker'!$P:$P,$A10,'Supplier Pipeline Tracker'!$T:$T,"<>") -> 0 | I10: =COUNTIFS('Supplier Pipeline Tracker'!$P:$P,$A10,'Supplier Pipeline Tracker'!$S:$S,"Y") -> 0 | J10: =COUNTIFS('Supplier Pipeline Tracker'!$P:$P,$A10,'Supplier Pipeline Tracker'!$AE:$AE,"<>") -> 0 | K10: =SUM($E$5:$E10) -> 0 | L10: =$K10/50 -> 0 | M10: Green
A11: TOTAL (to date) | D11: =SUM(D5:D10) -> 22 | E11: =SUM(E5:E10) -> 0 | K11: =K10 -> 0 | L11: =K11/50 -> 0

Sheet Contract & Document Status
A1: Contract & Document Status
A2: One row per contract document. ALL international docs must be in Calyx Containers' legal name.
A4: Vendor_ID | B4: Vendor_Name | C4: Doc_Type | D4: Calyx_Legal_Entity_Named | E4: Sent_Date | F4: Signed_Date | G4: Countersigned | H4: IP_Clause | I4: Defect_Penalty_Clause | J4: NonCompete_24mo | K4: Milestone_Payment_Terms | L4: ROFR_Steven_Staff | M4: Status | N4: Notes

Sheet Risk Register
A1: Risk Register
A2: Review at every bi-weekly sprint sync. Escalate per the SLT 24-hour rule.
A4: # | B4: Risk | C4: Likelihood | D4: Impact | E4: Mitigation | F4: Owner | G4: Trigger / Early signal | H4: Status
A5: 1 | B5: 2-week contracting erodes diligence | C5: M-H | D5: H | E5: Contracted != qualified; MSA carries trial+PSI exit ramp; cap full-run spend until AQL pass | F5: Cory | G5: Trial/PSI fails after signing | H5: Open
A6: 2 | B6: Legal countersignature throughput (6 in Wks 3-4) | C6: M-H | D6: H | E6: Pre-approve 2 master templates (Wk 0); 48-hr Legal SLA; redline-only; off-template -> 24-hr escalation | F6: Legal / A: Cory | G6: Any MSA waiting >48h | H6: Open
A7: 3 | B7: Intl qualification lag (PSI/customs can't fit in-sprint) | C7: H | D7: M-H | E7: Gate = contracted + tour + capability; go/no-go Wks 6-8; never promise qualified intl in 2 wks | F7: Steven / A: Cory | G7: PSI slips past Wk 8 | H7: Open
A8: 4 | B8: Warm-pipeline depletion after Wave 2 | C8: M-H | D8: H | E8: Identification runs a sprint ahead; continuously feed pipeline | F8: Cory | G8: <5 named candidates per open slot | H8: Open
A9: 5 | B9: Section 301 tariffs raise China landed cost | C9: H | D9: H | E9: China+Vietnam dual-country Day 1; >=1 Vietnam by Wave 2; model landed cost both origins | F9: Steven / A: Cory | G9: Tariff action announced | H9: Open
A10: 6 | B10: Key-person dependency on Steven | C10: M | D10: H | E10: All docs in Calyx name; IP clause; 24-mo non-compete; ROFR on 3 staff; Cory holds docs + relationship map | F10: Cory | G10: Steven availability change | H10: Open
A11: 7 | B11: MOQ / deposit cash exposure | C11: M | D11: H | E11: Milestone/phase-gate payments; trials first; per-sprint deposit cap; breach -> escalate to Heath | F11: Cory / A: Heath | G11: Deposit request > cap | H11: Open
A12: 8 | B12: Quality / prepress failure (flex digital art) | C12: M | D12: H | E12: Mandatory 3rd-party PSI at AQL; trials before full runs; defect penalty in every MSA | F12: Quality / A: Cory | G12: Trial defect rate > AQL | H12: Open
A13: 9 | B13: Guangdong supplier concentration | C13: M | D13: M | E13: Treat Guangdong-only categories as single-source; require T2 outside Guangdong/in Vietnam | F13: Cory | G13: Category with only Guangdong T1 | H13: Open
A14: 10 | B14: PackOS / Command integration gaps | C14: M | D14: M-H | E14: Define handoff fields at Wave 1; vendor not 'done' until data lands; interim sheet + backfill | F14: Cory | G14: Data not landing in PackOS | H14: Open
A15: 11 | B15: CNY blackout (~3 wks Jan/Feb, annual) | C15: H | D15: M-H | E15: Bake into lead-time KPI; pre-CNY buffer builds; non-issue for mid-2026 start, recurring after | F15: Steven / A: Cory | G15: Approaching Jan | H15: Open

Sheet Reference Lists
A1: Reference Lists
A2: Dropdown source values — edit a column to change the dropdowns used across the tracker.
A3: Track | B3: Tier | C3: Primary/Secondary | D3: Stage | E3: Category | F3: Capability Verified | G3: PSI Status | H3: RAG | I3: Yes/No
A4: Domestic | B4: T1 | C4: Primary | D4: Identify | E4: Domestic Digital | F4: Y | G4: Not started | H4: Green | I4: Y
A5: International | B5: T2 | C5: Secondary | D5: Screen | E5: Domestic Flexographic | F5: N | G5: Booked | H5: Amber | I5: N
B6: T3 | D6: Qualify | E6: Domestic Rotogravure | F6: Pending | G6: Passed | H6: Red
D7: NDA | E7: International Digital | G7: Failed
D8: RFQ | E8: International Rotogravure | G8: N/A
D9: Sample | E9: Labels
D10: Tour/Audit | E10: Shrinks
D11: Contracted | E11: Flex Materials
D12: Qualifying | E12: Tins
D13: Active | E13: Pop-top Tubes
D14: Parked | E14: Boxes (Rigid/CR)
E15: Boxes (SBS/Display)
