Workbook

Sheet Vendor Tier Overview
A1: Criteria | B1: Description | C1: Weight (%)
A2: Business Impact | B2: Would disruption affect revenue, compliance, or quality? | C2: 0.35
A3: Spend Volume | B3: What is the annual spend with this vendor? | C3: 0.2
A4: Substitutability | B4: How easily can this vendor be replaced? | C4: 0.2
A5: Supply Complexity | B5: Custom tooling, regulatory dependencies, or IP involved? | C5: 0.15
A6: Supplier Relationship | B6: Strategic partner or transactional relationship? | C6: 0.1
A9: Business Impact
A10: Score | B10: Definition | C10: Example Vendors
A11: 5 - Critical | B11: Disruption would halt core operations, affect regulated products, or lead to major revenue loss | C11: Primary packaging (rigid containers), licensed resins
A12: 4 - High | B12: Disruption would significantly delay customer orders or require expensive workaround/substitute | C12: Key label suppliers, large freight carriers
A13: 3 - Moderate | B13: Delays would impact operations but alternatives exist or buffer inventory is available | C13: Flexible packaging, regional distributors
A14: 2 - Low | B14: Disruption causes inefficiencies or slight cost increases but is manageable | C14: Corrugate vendors, non-critical custom labels
A15: 1 - Minimal | B15: No direct impact on products or customers; easily substituted | C15: Office supplies, promotional material providers
A17: Spend Volume
A18: Score | B18: Criteria | C18: Example
A19: 5 | B19: Contribute to 80% of total vendor spend | C19: Rigid container supplier
A20: 4 | B20: N/A
A21: 3 | B21: Contribute to 81%-95% of total vendor spend | C21: Secondary packaging or service vendors
A22: 2 | B22: N/A
A23: 1 | B23: Contribute to 96%-100% of total vendor spend | C23: Promotional or one-time vendors
A25: Substitutability
A26: Score | B26: Criteria | C26: Example
A27: 5 | B27: No substitute exists; proprietary, licensed, or uniquely qualified supplier | C27: Custom CR packaging or tooling vendor
A28: 4 | B28: Very limited substitutes; switching takes 3+ months or regulatory rework | C28: Specialized label supplier with cannabis compliance knowledge
A29: 3 | B29: Some substitutes exist; 30–90 day lead time to switch | C29: Branded carton printers
A30: 2 | B30: Easily substitutable with minor effort or approval | C30: Common shipping materials or brokers
A31: 1 | B31: Fully commoditized; substitutes immediately available | C31: Office supplies or standard MRO items
A33: Supply Complexity
A34: Score | B34: Criteria | C34: Example
A35: 5 | B35: High complexity: custom specifications, long tooling lead times, tight tolerances | C35: CR-certified containers with custom design
A36: 4 | B36: Moderate-high: requires ongoing engineering collaboration or special approvals | C36: Multi-layered labels or film
A37: 3 | B37: Moderate: multi-step quoting, but largely repeatable products | C37: Printed cartons with dielines
A38: 2 | B38: Low complexity: catalog-based, limited configuration | C38: Predefined SKUs, blank packaging
A39: 1 | B39: Very simple: off-the-shelf, plug-and-play | C39: Office chairs, janitorial supplies
A41: Supplier Relationship
A42: Score | B42: Criteria | C42: Example
A43: 5 | B43: Long-term strategic partner; involved in product development or innovation | C43: Co-developing sustainable packaging
A44: 4 | B44: Close operational partner with performance tracking and quarterly reviews | C44: Key vendor with SLA and dashboard in place
A45: 3 | B45: Stable relationship with repeat orders but limited engagement | C45: Recurring vendor, no formal governance
A46: 2 | B46: Transactional: used when needed, minimal continuity | C46: Local printers or temporary vendors
...

Sheet Vendor Tier Analysis
A1: Last Updated | C1: 46174 | E1: Bills Received | H1: 0.35 | I1: 0.2 | J1: 0.2 | K1: 0.15 | L1: 0.1
A2: Vendor | B2: Substitutability | C2: Class | D2: Geography | E2: Total | F2: % of Spend | G2: Running | H2: Business Impact | I2: Spend Volume | J2: Substitutability | K2: Supply Complexity | L2: Supplier Relationship | M2: Weighted Tier | N2: Tier
A3: Compax Packaging | B3: Propritary | C3: Plastic Containers | D3: USA | E3: =iferror(VLOOKUP(A3,Q:R,2,false),0) -> 918377.34 | F3: =E3/(SUM($E$3:$E$40)) -> 0.30628492 | G3: =SUM($F$3:F3) -> 0.30628492 | H3: 5 | I3: =IF(G3<0.8,5,IF(G3<0.95,3,1)) -> 5 | J3: =IF(B3="Propritary",5,IF(B3="Long",4,IF(B3="Medium",3,IF(B3="Short",2,1)))) -> 5 | K3: 5 | L3: 5 | M3: =SUMPRODUCT(H3:L3,$H$1:$L$1) -> 5 | N3: Tier 1
A4: DazPak | B4: Medium | C4: Flexographic Flexible Packaging | D4: USA | E4: =iferror(VLOOKUP(A4,Q:R,2,false),0) -> 504514.92 | F4: =E4/(SUM($E$3:$E$40)) -> 0.16825906 | G4: =SUM($F$3:F4) -> 0.47454398 | H4: 4 | I4: =IF(G4<0.8,5,IF(G4<0.95,3,1)) -> 5 | J4: =IF(B4="Propritary",5,IF(B4="Long",4,IF(B4="Medium",3,IF(B4="Short",2,1)))) -> 3 | K4: 3 | L4: 5 | M4: =SUMPRODUCT(H4:L4,$H$1:$L$1) -> 3.95 | N4: Tier 1
A5: Logistics Plus | B5: Short | C5: Shipping | D5: USA | E5: =iferror(VLOOKUP(A5,Q:R,2,false),0) -> 331979.79 | F5: =E5/(SUM($E$3:$E$40)) -> 0.11071746 | G5: =SUM($F$3:F5) -> 0.58526144 | H5: 4 | I5: =IF(G5<0.8,5,IF(G5<0.95,3,1)) -> 5 | J5: =IF(B5="Propritary",5,IF(B5="Long",4,IF(B5="Medium",3,IF(B5="Short",2,1)))) -> 2 | K5: 1 | L5: 3 | M5: =SUMPRODUCT(H5:L5,$H$1:$L$1) -> 3.25 | N5: Tier 2
A6: Ross Print and Packaging | B6: Short | C6: Midweb Digital Flexible Packaging | D6: USA | E6: =iferror(VLOOKUP(A6,Q:R,2,false),0) -> 224831.89 | F6: =E6/(SUM($E$3:$E$40)) -> 0.074982922 | G6: =SUM($F$3:F6) -> 0.66024436 | H6: 4 | I6: =IF(G6<0.8,5,IF(G6<0.95,3,1)) -> 5 | J6: =IF(B6="Propritary",5,IF(B6="Long",4,IF(B6="Medium",3,IF(B6="Short",2,1)))) -> 2 | K6: 3 | L6: 4 | M6: =SUMPRODUCT(H6:L6,$H$1:$L$1) -> 3.65 | N6: Tier 1
A7: MACTAC (Morgan Adhesives Co LLC) | B7: Medium | C7: Label Substrates | D7: USA | E7: =iferror(VLOOKUP(A7,Q:R,2,false),0) -> 187425.85 | F7: =E7/(SUM($E$3:$E$40)) -> 0.062507761 | G7: =SUM($F$3:F7) -> 0.72275212 | H7: 3 | I7: =IF(G7<0.8,5,IF(G7<0.95,3,1)) -> 5 | J7: =IF(B7="Propritary",5,IF(B7="Long",4,IF(B7="Medium",3,IF(B7="Short",2,1)))) -> 3 | K7: 2 | L7: 4 | M7: =SUMPRODUCT(H7:L7,$H$1:$L$1) -> 3.35 | N7: Tier 2
A8: Indigo America Inc | B8: Propritary | C8: Printer Inks | D8: USA | E8: =iferror(VLOOKUP(A8,Q:R,2,false),0) -> 142645.94 | F8: =E8/(SUM($E$3:$E$40)) -> 0.047573365 | G8: =SUM($F$3:F8) -> 0.77032548 | H8: 5 | I8: =IF(G8<0.8,5,IF(G8<0.95,3,1)) -> 5 | J8: =IF(B8="Propritary",5,IF(B8="Long",4,IF(B8="Medium",3,IF(B8="Short",2,1)))) -> 5 | K8: 5 | L8: 4 | M8: =SUMPRODUCT(H8:L8,$H$1:$L$1) -> 4.9 | N8: Tier 1 | Q8: {Vendor} | R8: Total
A9: Stock Pkg | B9: Medium | C9: Flexible Packaging Substrate | D9: USA | E9: =iferror(VLOOKUP(A9,Q:R,2,false),0) -> 92581.76 | F9: =E9/(SUM($E$3:$E$40)) -> 0.030876629 | G9: =SUM($F$3:F9) -> 0.80120211 | H9: 3 | I9: =IF(G9<0.8,5,IF(G9<0.95,3,1)) -> 3 | J9: =IF(B9="Propritary",5,IF(B9="Long",4,IF(B9="Medium",3,IF(B9="Short",2,1)))) -> 3 | K9: 2 | L9: 4 | M9: =SUMPRODUCT(H9:L9,$H$1:$L$1) -> 2.95 | N9: Tier 2 | Q9: 1991 Parkway Blvd - SLC Payment Plan | R9: 55505.65
A10: Avery Dennison Corporation | B10: Medium | C10: Label Lamination | D10: USA | E10: =iferror(VLOOKUP(A10,Q:R,2,false),0) -> 85150.73 | F10: =E10/(SUM($E$3:$E$40)) -> 0.028398332 | G10: =SUM($F$3:F10) -> 0.82960044 | H10: 3 | I10: =IF(G10<0.8,5,IF(G10<0.95,3,1)) -> 3 | J10: =IF(B10="Propritary",5,IF(B10="Long",4,IF(B10="Medium",3,IF(B10="Short",2,1)))) -> 3 | K10: 2 | L10: 3 | M10: =SUMPRODUCT(H10:L10,$H$1:$L$1) -> 2.85 | N10: Tier 2 | Q10: 3i Law, LLC | R10: 2381.5
A11: Source One Packaging | B11: Long | C11: Shrink Bands | D11: China | E11: =iferror(VLOOKUP(A11,Q:R,2,false),0) -> 79981.25 | F11: =E11/(SUM($E$3:$E$40)) -> 0.026674276 | G11: =SUM($F$3:F11) -> 0.85627472 | H11: 4 | I11: =IF(G11<0.8,5,IF(G11<0.95,3,1)) -> 3 | J11: =IF(B11="Propritary",5,IF(B11="Long",4,IF(B11="Medium",3,IF(B11="Short",2,1)))) -> 4 | K11: 4 | L11: 3 | M11: =SUMPRODUCT(H11:L11,$H$1:$L$1) -> 3.7 | N11: Tier 1 | Q11: 50 HUNT STREET PROPERTY LLC | R11: 20215.4
A12: Reynolds Consumer Products (Presto Zippers) | B12: Long | C12: Flexible Packaging Zipper | D12: USA | E12: =iferror(VLOOKUP(A12,Q:R,2,false),0) -> 70125.5 | F12: =E12/(SUM($E$3:$E$40)) -> 0.023387318 | G12: =SUM($F$3:F12) -> 0.87966204 | H12: 3 | I12: =IF(G12<0.8,5,IF(G12<0.95,3,1)) -> 3 | J12: =IF(B12="Propritary",5,IF(B12="Long",4,IF(B12="Medium",3,IF(B12="Short",2,1)))) -> 4 | K12: 2 | L12: 3 | M12: =SUMPRODUCT(H12:L12,$H$1:$L$1) -> 3.05 | N12: Tier 3 | Q12: AB Graphic International Inc | R12: 20847.4
A13: KDX-Kangde Xin America LLC | B13: Short | C13: Flexible Packaging Lamination | D13: China | E13: =iferror(VLOOKUP(A13,Q:R,2,false),0) -> 49906.3 | F13: =E13/(SUM($E$3:$E$40)) -> 0.016644081 | G13: =SUM($F$3:F13) -> 0.89630612 | H13: 3 | I13: =IF(G13<0.8,5,IF(G13<0.95,3,1)) -> 3 | J13: =IF(B13="Propritary",5,IF(B13="Long",4,IF(B13="Medium",3,IF(B13="Short",2,1)))) -> 2 | K13: 2 | L13: 2 | M13: =SUMPRODUCT(H13:L13,$H$1:$L$1) -> 2.55 | N13: Tier 3 | Q13: Ace Recycling & Disposal | R13: 2130.42
A14: Taghleef Industries | B14: Short | C14: Flexible Packaging Lamination | D14: USA | E14: =iferror(VLOOKUP(A14,Q:R,2,false),0) -> 37684.98 | F14: =E14/(SUM($E$3:$E$40)) -> 0.01256819 | G14: =SUM($F$3:F14) -> 0.90887431 | H14: 1 | I14: =IF(G14<0.8,5,IF(G14<0.95,3,1)) -> 3 | J14: =IF(B14="Propritary",5,IF(B14="Long",4,IF(B14="Medium",3,IF(B14="Short",2,1)))) -> 2 | K14: 2 | L14: 2 | M14: =SUMPRODUCT(H14:L14,$H$1:$L$1) -> 1.85 | N14: Tier 3 | Q14: ACTEGA North America LLC | R14: 1432.12
A15: Morris Packaging LLC | B15: Medium | C15: Flexographic Flexible Packaging | D15: USA | E15: =iferror(VLOOKUP(A15,Q:R,2,false),0) -> 33246.66 | F15: =E15/(SUM($E$3:$E$40)) -> 0.011087981 | G15: =SUM($F$3:F15) -> 0.91996229 | I15: =IF(G15<0.8,5,IF(G15<0.95,3,1)) -> 3 | J15: =IF(B15="Propritary",5,IF(B15="Long",4,IF(B15="Medium",3,IF(B15="Short",2,1)))) -> 3 | M15: =SUMPRODUCT(H15:L15,$H$1:$L$1) -> 1.2 | N15: Tier 8 | Q15: ASAP Freight LLC | R15: 3551.65
A16: Custom Cones USA | B16: Long | C16: Pop Top Tubes | D16: USA | E16: =iferror(VLOOKUP(A16,Q:R,2,false),0) -> 28352.48 | F16: =E16/(SUM($E$3:$E$40)) -> 0.0094557396 | G16: =SUM($F$3:F16) -> 0.92941803 | I16: =IF(G16<0.8,5,IF(G16<0.95,3,1)) -> 3 | J16: =IF(B16="Propritary",5,IF(B16="Long",4,IF(B16="Medium",3,IF(B16="Short",2,1)))) -> 4 | M16: =SUMPRODUCT(H16:L16,$H$1:$L$1) -> 1.4 | N16: Tier 6 | Q16: Avery Dennison Corporation | R16: 85150.73
A17: Flex-Pack Engineering, Inc. | B17: Long | C17: Cure Material | D17: USA | E17: =iferror(VLOOKUP(A17,Q:R,2,false),0) -> 28141.27 | F17: =E17/(SUM($E$3:$E$40)) -> 0.0093852997 | G17: =SUM($F$3:F17) -> 0.93880333 | H17: 1 | I17: =IF(G17<0.8,5,IF(G17<0.95,3,1)) -> 3 | J17: =IF(B17="Propritary",5,IF(B17="Long",4,IF(B17="Medium",3,IF(B17="Short",2,1)))) -> 4 | K17: 4 | L17: 5 | M17: =SUMPRODUCT(H17:L17,$H$1:$L$1) -> 2.85 | N17: Tier 2 | Q17: BakerHostetler | R17: 95809
A18: Spectragraphics | B18: Medium | C18: Label Printer | D18: USA | E18: =iferror(VLOOKUP(A18,Q:R,2,false),0) -> 23654.17 | F18: =E18/(SUM($E$3:$E$40)) -> 0.0078888222 | G18: =SUM($F$3:F18) -> 0.94669215 | H18: 3 | I18: =IF(G18<0.8,5,IF(G18<0.95,3,1)) -> 3 | J18: =IF(B18="Propritary",5,IF(B18="Long",4,IF(B18="Medium",3,IF(B18="Short",2,1)))) -> 3 | K18: 3 | L18: 3 | M18: =SUMPRODUCT(H18:L18,$H$1:$L$1) -> 3 | N18: Tier 2 | Q18: BB Media Group, LLC | R18: 10150
A19: Propeller, Inc. | B19: Long | C19: FEP Inserter | D19: USA | E19: =iferror(VLOOKUP(A19,Q:R,2,false),0) -> 20997.51 | F19: =E19/(SUM($E$3:$E$40)) -> 0.0070028085 | G19: =SUM($F$3:F19) -> 0.95369496 | H19: 2 | I19: =IF(G19<0.8,5,IF(G19<0.95,3,1)) -> 1 | J19: =IF(B19="Propritary",5,IF(B19="Long",4,IF(B19="Medium",3,IF(B19="Short",2,1)))) -> 4 | K19: 1 | L19: 3 | M19: =SUMPRODUCT(H19:L19,$H$1:$L$1) -> 2.15 | N19: Tier 3 | Q19: Beckstrand Law Offices | R19: 8000
A20: Tedpack Company Limited | B20: Medium | C20: International Flexpack | D20: USA | E20: =iferror(VLOOKUP(A20,Q:R,2,false),0) -> 18657.39 | F20: =E20/(SUM($E$3:$E$40)) -> 0.006222363 | G20: =SUM($F$3:F20) -> 0.95991732 | I20: =IF(G20<0.8,5,IF(G20<0.95,3,1)) -> 1 | J20: =IF(B20="Propritary",5,IF(B20="Long",4,IF(B20="Medium",3,IF(B20="Short",2,1)))) -> 3 | M20: =SUMPRODUCT(H20:L20,$H$1:$L$1) -> 0.8 | N20: Tier 12 | Q20: BMD | R20: 8000
A21: Virtual Packaging | B21: Short | C21: Paperboard | D21: USA | E21: =iferror(VLOOKUP(A21,Q:R,2,false),0) -> 18163 | F21: =E21/(SUM($E$3:$E$40)) -> 0.0060574806 | G21: =SUM($F$3:F21) -> 0.9659748 | H21: 4 | I21: =IF(G21<0.8,5,IF(G21<0.95,3,1)) -> 1 | J21: =IF(B21="Propritary",5,IF(B21="Long",4,IF(B21="Medium",3,IF(B21="Short",2,1)))) -> 2 | K21: 3 | L21: 2 | M21: =SUMPRODUCT(H21:L21,$H$1:$L$1) -> 2.65 | N21: Tier 2 | Q21: Bottle Coatings | R21: -2432.18
A22: PakSouth | B22: Short | C22: Supplies | D22: USA | E22: =iferror(VLOOKUP(A22,Q:R,2,false),0) -> 13588.21 | F22: =E22/(SUM($E$3:$E$40)) -> 0.0045317579 | G22: =SUM($F$3:F22) -> 0.97050656 | I22: =IF(G22<0.8,5,IF(G22<0.95,3,1)) -> 1 | J22: =IF(B22="Propritary",5,IF(B22="Long",4,IF(B22="Medium",3,IF(B22="Short",2,1)))) -> 2 | M22: =SUMPRODUCT(H22:L22,$H$1:$L$1) -> 0.6 | N22: Tier 10 | Q22: Brandon Bonham | R22: 2500
A23: MP & D | B23: Short | C23: Supplies | D23: USA | E23: =iferror(VLOOKUP(A23,Q:R,2,false),0) -> 13500 | F23: =E23/(SUM($E$3:$E$40)) -> 0.0045023393 | G23: =SUM($F$3:F23) -> 0.9750089 | H23: 1 | I23: =IF(G23<0.8,5,IF(G23<0.95,3,1)) -> 1 | J23: =IF(B23="Propritary",5,IF(B23="Long",4,IF(B23="Medium",3,IF(B23="Short",2,1)))) -> 2 | K23: 3 | L23: 2 | M23: =SUMPRODUCT(H23:L23,$H$1:$L$1) -> 1.6 | N23: Tier 3 | Q23: Buffo's Termite & Pest Control | R23: 400
A24: California Packaging | B24: Short | C24: Supplies | D24: USA | E24: =iferror(VLOOKUP(A24,Q:R,2,false),0) -> 11680.39 | F24: =E24/(SUM($E$3:$E$40)) -> 0.0038954873 | G24: =SUM($F$3:F24) -> 0.97890439 | I24: =IF(G24<0.8,5,IF(G24<0.95,3,1)) -> 1 | J24: =IF(B24="Propritary",5,IF(B24="Long",4,IF(B24="Medium",3,IF(B24="Short",2,1)))) -> 2 | M24: =SUMPRODUCT(H24:L24,$H$1:$L$1) -> 0.6 | N24: Tier 4 | Q24: California Packaging | R24: 11680.39
A25: Kocher+Beck USA | B25: Medium | C25: Die Tools | D25: USA | E25: =iferror(VLOOKUP(A25,Q:R,2,false),0) -> 11512.39 | F25: =E25/(SUM($E$3:$E$40)) -> 0.0038394582 | G25: =SUM($F$3:F25) -> 0.98274385 | I25: =IF(G25<0.8,5,IF(G25<0.95,3,1)) -> 1 | J25: =IF(B25="Propritary",5,IF(B25="Long",4,IF(B25="Medium",3,IF(B25="Short",2,1)))) -> 3 | M25: =SUMPRODUCT(H25:L25,$H$1:$L$1) -> 0.8 | N25: Tier 7 | Q25: Chicago Exhibit Productions, Inc. | R25: 3354.33
A26: UBECHOI LIMITED | B26: Short | C26: Other | D26: China | E26: =iferror(VLOOKUP(A26,Q:R,2,false),0) -> 10000 | F26: =E26/(SUM($E$3:$E$40)) -> 0.0033350661 | G26: =SUM($F$3:F26) -> 0.98607891 | H26: 1 | I26: =IF(G26<0.8,5,IF(G26<0.95,3,1)) -> 1 | J26: =IF(B26="Propritary",5,IF(B26="Long",4,IF(B26="Medium",3,IF(B26="Short",2,1)))) -> 2 | K26: 1 | L26: 2 | M26: =SUMPRODUCT(H26:L26,$H$1:$L$1) -> 1.3 | N26: Tier 3 | Q26: Cleanmenders International | R26: 6150
A27: FEDEX | B27: Short | C27: Shipping | D27: USA | E27: =iferror(VLOOKUP(A27,Q:R,2,false),0) -> 7541.37 | F27: =E27/(SUM($E$3:$E$40)) -> 0.0025150968 | G27: =SUM($F$3:F27) -> 0.98859401 | H27: 1 | I27: =IF(G27<0.8,5,IF(G27<0.95,3,1)) -> 1 | J27: =IF(B27="Propritary",5,IF(B27="Long",4,IF(B27="Medium",3,IF(B27="Short",2,1)))) -> 2 | K27: 1 | L27: 2 | M27: =SUMPRODUCT(H27:L27,$H$1:$L$1) -> 1.3 | N27: Tier 3 | Q27: CLTV8 | R27: 11000
A28: Nobelus, LLC | B28: Short | C28: Label Lamination | D28: USA | E28: =iferror(VLOOKUP(A28,Q:R,2,false),0) -> 6550.12 | F28: =E28/(SUM($E$3:$E$40)) -> 0.0021845083 | G28: =SUM($F$3:F28) -> 0.99077852 | H28: 3 | I28: =IF(G28<0.8,5,IF(G28<0.95,3,1)) -> 1 | J28: =IF(B28="Propritary",5,IF(B28="Long",4,IF(B28="Medium",3,IF(B28="Short",2,1)))) -> 2 | K28: 2 | L28: 3 | M28: =SUMPRODUCT(H28:L28,$H$1:$L$1) -> 2.25 | N28: Tier 3 | Q28: Compax Packaging | R28: 918377.34
A29: Pacificolor, LLC | B29: Medium | C29: Printing Plates | D29: USA | E29: =iferror(VLOOKUP(A29,Q:R,2,false),0) -> 5065.73 | F29: =E29/(SUM($E$3:$E$40)) -> 0.0016894545 | G29: =SUM($F$3:F29) -> 0.99246797 | I29: =IF(G29<0.8,5,IF(G29<0.95,3,1)) -> 1 | J29: =IF(B29="Propritary",5,IF(B29="Long",4,IF(B29="Medium",3,IF(B29="Short",2,1)))) -> 3 | M29: =SUMPRODUCT(H29:L29,$H$1:$L$1) -> 0.8 | N29: Tier 9 | Q29: Conn Kavanaugh Rosenthal Peisch & Ford, LLP | R29: 60238
A30: JetFx Technologies | B30: Propritary | C30: Label Chemicals | D30: USA | E30: =iferror(VLOOKUP(A30,Q:R,2,false),0) -> 4642.2 | F30: =E30/(SUM($E$3:$E$40)) -> 0.0015482044 | G30: =SUM($F$3:F30) -> 0.99401618 | H30: 4 | I30: =IF(G30<0.8,5,IF(G30<0.95,3,1)) -> 1 | J30: =IF(B30="Propritary",5,IF(B30="Long",4,IF(B30="Medium",3,IF(B30="Short",2,1)))) -> 5 | K30: 1 | L30: 3 | M30: =SUMPRODUCT(H30:L30,$H$1:$L$1) -> 3.05 | N30: Tier 2 | Q30: CRC - Cannabis Research Coalition | R30: 8905.32
A31: Wink US LLC | B31: Medium | C31: Printing Plates | D31: USA | E31: =iferror(VLOOKUP(A31,Q:R,2,false),0) -> 4470 | F31: =E31/(SUM($E$3:$E$40)) -> 0.0014907746 | G31: =SUM($F$3:F31) -> 0.99550695 | I31: =IF(G31<0.8,5,IF(G31<0.95,3,1)) -> 1 | J31: =IF(B31="Propritary",5,IF(B31="Long",4,IF(B31="Medium",3,IF(B31="Short",2,1)))) -> 3 | M31: =SUMPRODUCT(H31:L31,$H$1:$L$1) -> 0.8 | N31: Tier 14 | Q31: Creative Bend Films (Caroline Boyd Productions, LLC) | R31: 3000
A32: ASAP Freight LLC | B32: Short | C32: Shipping | D32: USA | E32: =iferror(VLOOKUP(A32,Q:R,2,false),0) -> 3551.65 | F32: =E32/(SUM($E$3:$E$40)) -> 0.0011844988 | G32: =SUM($F$3:F32) -> 0.99669145 | H32: 1 | I32: =IF(G32<0.8,5,IF(G32<0.95,3,1)) -> 1 | J32: =IF(B32="Propritary",5,IF(B32="Long",4,IF(B32="Medium",3,IF(B32="Short",2,1)))) -> 2 | K32: 1 | L32: 3 | M32: =SUMPRODUCT(H32:L32,$H$1:$L$1) -> 1.4 | N32: Tier 3 | Q32: Crews Consulting Group Payment Plan | R32: 1600
A33: H. Loeb Corporation | B33: Long | C33: FEP Die Cutting | D33: USA | E33: =iferror(VLOOKUP(A33,Q:R,2,false),0) -> 2400 | F33: =E33/(SUM($E$3:$E$40)) -> 0.00080041587 | G33: =SUM($F$3:F33) -> 0.99749187 | H33: 4 | I33: =IF(G33<0.8,5,IF(G33<0.95,3,1)) -> 1 | J33: =IF(B33="Propritary",5,IF(B33="Long",4,IF(B33="Medium",3,IF(B33="Short",2,1)))) -> 4 | K33: 3 | L33: 3 | M33: =SUMPRODUCT(H33:L33,$H$1:$L$1) -> 3.15 | N33: Tier 2 | Q33: CROWN PACKAGING CORP | R33: 876.8
A34: UPS | B34: Short | C34: Shipping | D34: USA | E34: =iferror(VLOOKUP(A34,Q:R,2,false),0) -> 2271.2 | F34: =E34/(SUM($E$3:$E$40)) -> 0.00075746022 | G34: =SUM($F$3:F34) -> 0.99824933 | H34: 3 | I34: =IF(G34<0.8,5,IF(G34<0.95,3,1)) -> 1 | J34: =IF(B34="Propritary",5,IF(B34="Long",4,IF(B34="Medium",3,IF(B34="Short",2,1)))) -> 2 | K34: 1 | L34: 3 | M34: =SUMPRODUCT(H34:L34,$H$1:$L$1) -> 2.1 | N34: Tier 3 | Q34: Custom Cones USA | R34: 28352.48
A35: Sun Centre USA Inc | B35: Medium | C35: Flexible Packaging Converter | D35: USA | E35: =iferror(VLOOKUP(A35,Q:R,2,false),0) -> 1580.55 | F35: =E35/(SUM($E$3:$E$40)) -> 0.00052712388 | G35: =SUM($F$3:F35) -> 0.99877645 | H35: 3 | I35: =IF(G35<0.8,5,IF(G35<0.95,3,1)) -> 1 | J35: =IF(B35="Propritary",5,IF(B35="Long",4,IF(B35="Medium",3,IF(B35="Short",2,1)))) -> 3 | K35: 2 | L35: 3 | M35: =SUMPRODUCT(H35:L35,$H$1:$L$1) -> 2.45 | N35: Tier 3 | Q35: Cyber Advisors (Wasatch IT). | R35: 20480.94
A36: ACTEGA North America LLC | B36: Medium | C36: Label Chemicals | D36: USA | E36: =iferror(VLOOKUP(A36,Q:R,2,false),0) -> 1432.12 | F36: =E36/(SUM($E$3:$E$40)) -> 0.00047762149 | G36: =SUM($F$3:F36) -> 0.99925407 | H36: 3 | I36: =IF(G36<0.8,5,IF(G36<0.95,3,1)) -> 1 | J36: =IF(B36="Propritary",5,IF(B36="Long",4,IF(B36="Medium",3,IF(B36="Short",2,1)))) -> 3 | K36: 2 | L36: 3 | M36: =SUMPRODUCT(H36:L36,$H$1:$L$1) -> 2.45 | N36: Tier 3 | Q36: DazPak | R36: 504514.92
A37: CROWN PACKAGING CORP | B37: Short | C37: Supplies | D37: USA | E37: =iferror(VLOOKUP(A37,Q:R,2,false),0) -> 876.8 | F37: =E37/(SUM($E$3:$E$40)) -> 0.0002924186 | G37: =SUM($F$3:F37) -> 0.99954649 | I37: =IF(G37<0.8,5,IF(G37<0.95,3,1)) -> 1 | J37: =IF(B37="Propritary",5,IF(B37="Long",4,IF(B37="Medium",3,IF(B37="Short",2,1)))) -> 2 | M37: =SUMPRODUCT(H37:L37,$H$1:$L$1) -> 0.6 | N37: Tier 5 | Q37: Emerald X, LLC | R37: 6254.11
A38: Western Container | B38: Short | C38: Supplies | D38: USA | E38: =iferror(VLOOKUP(A38,Q:R,2,false),0) -> 486.44 | F38: =E38/(SUM($E$3:$E$40)) -> 0.00016223096 | G38: =SUM($F$3:F38) -> 0.99970872 | I38: =IF(G38<0.8,5,IF(G38<0.95,3,1)) -> 1 | J38: =IF(B38="Propritary",5,IF(B38="Long",4,IF(B38="Medium",3,IF(B38="Short",2,1)))) -> 2 | M38: =SUMPRODUCT(H38:L38,$H$1:$L$1) -> 0.6 | N38: Tier 13 | Q38: Enbridge Energy | R38: 1979.69
A39: K LASER TECHNOLOGY (USA) CO., LTD. | B39: Short | C39: Label Foil | D39: USA | E39: =iferror(VLOOKUP(A39,Q:R,2,false),0) -> 460.8 | F39: =E39/(SUM($E$3:$E$40)) -> 0.00015367985 | G39: =SUM($F$3:F39) -> 0.9998624 | H39: 2 | I39: =IF(G39<0.8,5,IF(G39<0.95,3,1)) -> 1 | J39: =IF(B39="Propritary",5,IF(B39="Long",4,IF(B39="Medium",3,IF(B39="Short",2,1)))) -> 2 | K39: 2 | L39: 2 | M39: =SUMPRODUCT(H39:L39,$H$1:$L$1) -> 1.8 | N39: Tier 3 | Q39: EQUIPMENT SHARE | R39: 40339.57
A40: Siegwerk EIC, LLC | B40: Medium | C40: Label Chemicals | D40: USA | E40: =iferror(VLOOKUP(A40,Q:R,2,false),0) -> 412.58 | F40: =E40/(SUM($E$3:$E$40)) -> 0.00013759816 | G40: =SUM($F$3:F40) -> 1 | I40: =IF(G40<0.8,5,IF(G40<0.95,3,1)) -> 1 | J40: =IF(B40="Propritary",5,IF(B40="Long",4,IF(B40="Medium",3,IF(B40="Short",2,1)))) -> 3 | M40: =SUMPRODUCT(H40:L40,$H$1:$L$1) -> 0.8 | N40: Tier 11 | Q40: EverGreen Line | R40: 3647
...

Sheet Flexible Packaging Capabilities
A1: Vendor | B1: Midweb Digital Printing | C1: Flexographic Printing | D1: Rotograuvre Printing | E1: SUP/ Layflat Bag Converting | F1: Flat Bottom Pouch Converting | G1: Spot Varnish | H1: Solventless Lamination | I1: Thermal Lamination | J1: Stated Margin
A2: DazPak | B2: No | C2: Yes | D2: No | E2: Yes | F2: Yes | G2: Yes | H2: Yes | I2: No | J2: 15% or Less
A3: Ross Print and Packaging | B3: Yes | C3: No | D3: No | E3: Yes | F3: No | G3: Yes | H3: No | I3: Yes | J3: 15% - 25%
A4: Takigawa Corporation America | B4: No | C4: No | D4: Yes | E4: Yes | F4: Yes | H4: Yes | I4: No
A5: CannaZip | B5: Yes | C5: Yes | D5: Yes | E5: Yes | F5: Yes | G5: Yes
A6: Reynolds Packaging LLC | B6: No | C6: No | D6: No | E6: Yes | F6: No | G6: No | H6: No | I6: No
A7: Inkworks | B7: Yes | C7: No | D7: No | E7: Yes | F7: No | G7: No | H7: Yes | I7: No
A8: Print Rush LLC | B8: Yes | C8: No | D8: No | E8: No | F8: No | G8: No | H8: No | I8: Yes | J8: 0.3

Sheet Materials  Finished Goods
A1: Vendor | B1: Tier | C1: Category | D1: Sub Category | E1: Stage | F1: Capabilities | G1: Locations | H1: Documents | I1: Calyx POC | J1: Vendor POC | K1: Vendor POC Phone Number | L1: Vendor POC Email
A2: American Durafilm | B2: =iferror(VLOOKUP(A2,'Vendor Tier Analysis'!A:N,11,false),"") -> 5 | C2: Finished Goods Components | D2: FEP Forming | E2: 7 - Active | F2: FEP Film Sheeting Die Cutting Thermoforming | I2: Cory Timmons | J2: Mitchel Mei | K2: 508-429-8000 | L2: jgoodwin@americandurafilm.com
A3: Avery Dennison Corporation | B3: =iferror(VLOOKUP(A3,'Vendor Tier Analysis'!A:N,11,false),"") -> 2 | C3: Raw Materials - Labels | D3: Facestock | E3: 7 - Active | F3: Roll Stock Label Material Minimal Flexible packaging Materials | I3: Cory Timmons | J3: Ashleigh Kosanka | K3: 419-618-5965 | L3: Ashleigh.kosanka@averydennison.com
A4: Compax Packaging | B4: =iferror(VLOOKUP(A4,'Vendor Tier Analysis'!A:N,11,false),"") -> 5 | C4: Finished Goods - Rigid | D4: Injection molding | E4: 7 - Active | F4: Injection Molding | G4: Salt Lake City, UT | I4: Cory Timmons | J4: Danelle Devine Lucinda Blackburn | K4: 801-440-0581 ‪‪208-313-1533 | L4: danelle@compaxpackaging.com, lblackburn@compaxpackaging.com
A5: H. Loeb Corporation | B5: =iferror(VLOOKUP(A5,'Vendor Tier Analysis'!A:N,11,false),"") -> 3 | C5: Finished Goods Components | D5: FEP Die Cutting | E5: 7 - Active | F5: Die cutting CNC Routing Laser Cutting | I5: Cory Timmons | J5: Geoffrey Faucher | K5: 508 944-8629 | L5: gfaucher@hloeb.com
A6: HP Indigo | B6: =iferror(VLOOKUP(A6,'Vendor Tier Analysis'!A:N,11,false),"") | C6: Raw Materials - Labels | D6: Ink | E6: 7 - Active | I6: Cory Timmons | J6: Zak Callahan | K6: 858-449-6969 | L6: zak.callahan@hp.com
A7: Logistics Plus | B7: =iferror(VLOOKUP(A7,'Vendor Tier Analysis'!A:N,11,false),"") -> 1 | C7: Logistics | D7: Distribution | E7: 7 - Active | F7: LTL FTL International 3PL services | I7: Cory Timmons | J7: Danny Yunes | L7: daniel.yunes@logisticsplus.com
A8: MACTAC (Morgan Adhesives Co LLC) | B8: =iferror(VLOOKUP(A8,'Vendor Tier Analysis'!A:N,11,false),"") -> 2 | C8: Raw Materials - Labels | D8: Facestock | E8: 7 - Active | F8: Roll Stock Label Material | I8: Cory Timmons | J8: Duane Stevenson | K8: 916-715-9332 | L8: orders@mactac.com
A9: Propeller Warehouse Inc | B9: =iferror(VLOOKUP(A9,'Vendor Tier Analysis'!A:N,11,false),"") | C9: Finished Goods Components | D9: FEP Insert | E9: 7 - Active | F9: Kitting/ Assembly 3PL Services | G9: Santiquin, UT | I9: Cory Timmons | J9: Avery Christensen | K9: 801-592-1805 | L9: avery@propellerinc.com
A10: Rotometrics/ Maxacess | B10: =iferror(VLOOKUP(A10,'Vendor Tier Analysis'!A:N,11,false),"") | C10: Raw Materials | D10: Die | E10: 7 - Active | I10: Cory Timmons | J10: Phil Taylor | K10: 909-957-2128
A11: UPS | B11: =iferror(VLOOKUP(A11,'Vendor Tier Analysis'!A:N,11,false),"") -> 1 | C11: Logistics | D11: Parcel | E11: 7 - Active | F11: Parcel Shipping | I11: Cory Timmons
A12: Virtual Packaging | B12: =iferror(VLOOKUP(A12,'Vendor Tier Analysis'!A:N,11,false),"") -> 3 | C12: Finished Goods | D12: Boxes | E12: 7 - Active | F12: Digital Box Printing/ converting Spot Varnish Foil | G12: Grapevine, TX | I12: Cory Timmons | J12: Jodie Echols | K12: 817-714-7129 | L12: jodie@virtualpackaging.com
A13: Dazpak | B13: =iferror(VLOOKUP(A13,'Vendor Tier Analysis'!A:N,11,false),"") -> 3 | C13: Finished Goods | D13: Flexible Packaging | E13: 7 - Active | F13: Flexographic Printing Flexible Packaging Converting - K Seal - 3 side seal (Top/Bottom) - CR Zipper - Non CR Zipper Inolok Zipper Box Pouch Converting Storage Available Slitting Laminating | G13: Southern California Columbus, Ohio | I13: Cory Timmons | J13: Kevin Vance | K13: 916-716-7907 | L13: kvance@dazpak.com
A14: Ross Print and Packaging | B14: =iferror(VLOOKUP(A14,'Vendor Tier Analysis'!A:N,11,false),"") -> 3 | C14: Finished Goods | D14: Flexible Packaging | E14: 7 - Active | F14: Mid-web Digital Printing Lamination Spot Varnish Flexible Packaging Converting | G14: Spokane, WA | I14: Cory Timmons | J14: Kerry Ann Kauder | K14: 509-954-5844 | L14: kkauder@rossprint.com
A15: Print Rush LLC | B15: =iferror(VLOOKUP(A15,'Vendor Tier Analysis'!A:N,11,false),"") | C15: Finished Goods | D15: Flexible Packaging | E15: 7 - Active | F15: Mid-web Digital Printing Lamination | G15: Orem, UT | I15: Cory Timmons | J15: Hugh Olmstead | K15: 801-845-6525 | L15: hugh@printrush.net
A16: Source One Packaging | B16: =iferror(VLOOKUP(A16,'Vendor Tier Analysis'!A:N,11,false),"") -> 4 | C16: Finished Goods | D16: Shrink Bands | E16: 7 - Active | F16: Shrink Sleeves Flexographic Flexpack Dessicants | I16: Cory Timmons | J16: Nick Griffo | K16: 631-258-3073 | L16: ng@sourceonepackagingllc.com
A17: Sun Centre USA Inc | B17: =iferror(VLOOKUP(A17,'Vendor Tier Analysis'!A:N,11,false),"") -> 2 | C17: Finished Goods | D17: Converting | E17: 7 - Active | F17: Flexible Packaging Converting - K Seal - 3 side seal (Top/Bottom) - CR Zipper - Non CR Zipper | I17: Cory Timmons | J17: Sean Pease | K17: 224-699-9058 | L17: cust.serv@suncentre.us
A18: Nobelus, LLC | B18: =iferror(VLOOKUP(A18,'Vendor Tier Analysis'!A:N,11,false),"") -> 2 | C18: Raw Materials | D18: Laminate | E18: 7 - Active | I18: Cory Timmons | J18: Sara Perry | L18: sara.perry@nobelus.com
A19: ACTEGA North America, Inc. | B19: =iferror(VLOOKUP(A19,'Vendor Tier Analysis'!A:N,11,false),"") | C19: Raw Materials | D19: Varinish/ Primer | E19: 7 - Active | I19: Cory Timmons | J19: Marc Pittier | K19: 925-451-1960 | L19: marc.pittier@altana.com
A20: CTI | B20: =iferror(VLOOKUP(A20,'Vendor Tier Analysis'!A:N,11,false),"") | C20: Raw Materials | D20: Ink | E20: 7 - Active | I20: Cory Timmons | J20: Tracy Lewis | K20: 719-592-1557 | L20: tlewis@ctiinks.com
A21: Fedex | B21: =iferror(VLOOKUP(A21,'Vendor Tier Analysis'!A:N,11,false),"") -> 1 | C21: Logistics | D21: Parcel | E21: 7 - Active | I21: Cory Timmons
A22: Inhance Technologies LLC | B22: =iferror(VLOOKUP(A22,'Vendor Tier Analysis'!A:N,11,false),"") -> 3 | C22: Raw Materials | D22: Flourination | E22: 7 - Active | I22: Cory Timmons | J22: Chris Ridenour | K22: 281-813-8144 | L22: cridenour@inhancetechnologies.com
A23: JetFx Inc. | B23: =iferror(VLOOKUP(A23,'Vendor Tier Analysis'!A:N,11,false),"") | C23: Raw Materials | D23: Varinish/ Primer | E23: 7 - Active | I23: Cory Timmons | J23: Chris Padilla | L23: consumables@jetfx.com
A24: K LASER TECHNOLOGY (USA) CO., LTD. | B24: =iferror(VLOOKUP(A24,'Vendor Tier Analysis'!A:N,11,false),"") -> 2 | C24: Raw Materials | D24: Foil | E24: 7 - Active | I24: Cory Timmons | J24: Richard Jackson | K24: 561-373-0251 | L24: richardj@coldfoil.com
A25: Kurz | B25: =iferror(VLOOKUP(A25,'Vendor Tier Analysis'!A:N,11,false),"") | C25: Raw Materials | D25: Foil | E25: 7 - Active | I25: Cory Timmons | J25: Michael Aumann | K25: 704-519-6391 | L25: Michael.Aumann@kurzusa.com
A26: Pacific Color | B26: =iferror(VLOOKUP(A26,'Vendor Tier Analysis'!A:N,11,false),"") | C26: Raw Materials | D26: Plate | E26: 7 - Active | I26: Cory Timmons | J26: Jason Jordan | K26: 801-721-6355 | L26: sales@pacificolor.com
A27: S-One | B27: =iferror(VLOOKUP(A27,'Vendor Tier Analysis'!A:N,11,false),"") -> 2 | C27: Raw Materials | D27: Varinish/ Primer | E27: 7 - Active | I27: Cory Timmons | J27: Haley Hollister | K27: 941-866-6125
A28: Siegwerk Environmental Inks | B28: =iferror(VLOOKUP(A28,'Vendor Tier Analysis'!A:N,11,false),"") | C28: Raw Materials | D28: Varinish/ Primer | E28: 7 - Active | I28: Cory Timmons | J28: Jake Melcher | K28: 719-332-1920 | L28: jake.melcher@siegwerk.com
A29: Spectragraphics | B29: =iferror(VLOOKUP(A29,'Vendor Tier Analysis'!A:N,11,false),"") -> 3 | C29: Finished Goods | D29: Labels | E29: 7 - Active | I29: Cory Timmons | J29: Erik Rodriguez | L29: erikr@spectragraphics.com
A30: Vision Automated Fulfillment | B30: =iferror(VLOOKUP(A30,'Vendor Tier Analysis'!A:N,11,false),"") | C30: Distribution | D30: Off Site Storage | E30: 7 - Active | I30: Cory Timmons | J30: Tracy York | K30: 801-651-7048 | L30: Tracy@visionaf.com
A31: Wellpac (Brokered through Compax) | B31: =iferror(VLOOKUP(A31,'Vendor Tier Analysis'!A:N,11,false),"") | C31: Finished Goods | D31: Injection molding | E31: 7 - Active | I31: Cory Timmons | J31: Danelle Devine Lucinda Blackburn | K31: 801-440-0581 ‪‪208-313-1533 | L31: danelle@compaxpackaging.com, lblackburn@compaxpackaging.com
A32: Wink | B32: =iferror(VLOOKUP(A32,'Vendor Tier Analysis'!A:N,11,false),"") | C32: Raw Materials | D32: Die | E32: 7 - Active | I32: Cory Timmons | J32: Dreana Helmick | K32: 704-804-3220 | L32: dreanah@wink-us.com
A33: Reynolds Packaging LLC | B33: =iferror(VLOOKUP(A33,'Vendor Tier Analysis'!A:N,11,false),"") -> 3 | C33: Finished Goods | D33: Flexible Packaging | E33: 7 - Active | F33: Flexible Packaging Converting - K Seal - 3 side seal (Top/Bottom) - CR Zipper - Non CR Zipper | G33: Green Bay, WI | I33: Cory Timmons
A34: Morris Packaging

Sheet Utilities Machines Facilities
A1: Vendor | B1: Category | C1: Sub Category | D1: Stage | E1: Capabilities | F1: Locations | G1: Documents | H1: Calyx POC | I1: Vendor POC | J1: Vendor POC Phone Number | K1: Vendor POC Email
A2: AB Graphics | B2: Machinery | C2: Finishing Machine | D2: 7 - Active | H2: Cory Timmons | I2: Mitch Ogran Nate Barker | J2: 951-312-8755 Parts | K2: mitch@abgintusa.com parts@abcint.com
A3: Dominion Energy | B3: Utilities | C3: Utilities | D3: 7 - Active | H3: Cory Timmons | J3: 800-323-5517
A4: Dupre Solutions | B4: Machinery | C4: Application Equipment | D4: 7 - Active | H4: Cory Timmons | I4: Isaac Dupre | K4: Isaac@dupre-solutions.com
A5: Haupt Electrical | B5: Facilities | C5: Electrical | D5: 7 - Active | H5: Cory Timmons | J5: 801-489-6565
A6: Hybrid Software USA | B6: Software | C6: Prepress | D6: 7 - Active | H6: Cory Timmons | I6: Eric Bateman | J6: 215-550-6243 | K6: ericb@hybridsoftware.com
A7: Jani-Serv Inc | B7: Facilities | C7: Cleaner | D7: 7 - Active | H7: Cory Timmons | I7: Mario Camargo | J7: 801-508-4933 | K7: janiservut@gmail.com
A8: Jones Heating & Air Conditioning | B8: Facilities | C8: HVAC | D8: 7 - Active | H8: Cory Timmons | I8: Dion Jones | J8: 801-972-8557
A9: Label Traxx | B9: Software | C9: Label Manufacturing | D9: 7 - Active | H9: Cory Timmons | I9: Dorothy Asboth Ken Wanderer | J9: 262-767-9977 414-774-9997 | K9: dorothy@labeltraxx.com kenw@labeltraxx.com
A10: Peak Alarm | B10: Facilities | C10: Security | D10: 7 - Active | H10: Cory Timmons | J10: 801-486-7231
A11: Qima | B11: Quality | C11: 3rd Party Inspection | D11: 7 - Active | H11: Cory Timmons
A12: Rewind Tables | B12: Machinery | C12: Machinery | D12: 7 - Active | H12: Cory Timmons | I12: Bart Buncke | J12: 801-592-1350
A13: Rocky Mountain Power | B13: Facilities | C13: Utilities | D13: 7 - Active | H13: Cory Timmons | I13: Acct #: 636134560011 | J13: 888-221-7070
A14: Rocky Mountain Recycling Services | B14: Facilities | C14: Recycler, Cardboard | D14: 7 - Active | G14: Link | H14: Cory Timmons | I14: Molly Sasine | J14: 801-931-4133 | K14: molly.sasine@rockymountainrecycling.com
A15: Sabol and Rice | B15: Facilities | C15: Generator | D15: 7 - Active | H15: Cory Timmons | J15: 801-973-2300
A16: West Valley City | B16: Facilities | C16: Municiple | D16: 7 - Active | H16: Cory Timmons | J16: 801-966-3600

Sheet Software SystemsVendors
B1: Active?
A2: Netsuite | B2: TRUE
A3: Outreach | B3: ?
A4: G-Suite | B4: TRUE
A5: Rippling | B5: TRUE
A6: Bennie | B6: TRUE
A7: Asana | B7: TRUE
A8: Slack | B8: TRUE
A9: Intercom | B9: ?
A10: Kixie | B10: ?
A11: Shopify | B11: TRUE
A12: Hubspot | B12: TRUE
A13: Bonusly | B13: TRUE
A14: Lucid Chart | B14: TRUE
A15: Adobe | B15: TRUE
A16: Freightquote | B16: FALSE
A17: Navisphere | B17: FALSE
A18: UPS | B18: TRUE
A19: Fedex | B19: TRUE
A20: Shipstation | B20: TRUE
A21: Tableau | B21: TRUE
A22: eShipPlus | B22: TRUE
... A38: PODS | B38: TRUE
A39: GroupGreeting | B39: ?
A40: CARM / Canada CBP | B40: TRUE
A41: Moresteam | B41: TRUE
A42: JazzHR | B42: TRUE
A43: Minitab | B43: FALSE
A44: Avalara | B44: TRUE
A45: Human Interest | B45: TRUE
A46: Quickbase | B46: FALSE
A47: Snackbox | B47: FALSE
A48: Electric AI | B48: FALSE
A49: Uline | B49: FALSE
A50: Shippo | B50: FALSE
A51: Form Publisher | B51: FALSE

Sheet Inactive Vendors
A1: Vendor | B1: Category | C1: Sub Category | D1: Stage | E1: Capabilities | F1: Locations | G1: Documents | H1: Calyx POC | I1: Vendor POC | J1: Vendor POC Phone Number | K1: Vendor POC Email
A2: Acucote Fredrigoni | C2: Facestock | D2: 8 - Not Approved/ Reapproval needed | H2: Rob Bullen | I2: Pat McGee | J2: 816-510-4267 | K2: patrick.mcgee@fedrigoni.com
A3: Anchor Hocking LLC | C3: Glass | D3: 8 - Not Approved/ Reapproval needed | H3: Cory Timmons | I3: Greg White | J3: 210-289-9010 | K3: Greg.white@anchorhocking.com
A4: Aspen Press | C4: Pouching | D4: 8 - Not Approved/ Reapproval needed | H4: Cory Timmons | I4: Roger Green | J4: 801-599-5748 | K4: roger@aspenpress.com
A5: ARC Intl | C5: Glass | D5: 8 - Not Approved/ Reapproval needed | H5: Cory Timmons
A6: Assempak | C6: FEP Inserter | D6: 8 - Not Approved/ Reapproval needed | H6: Cory Timmons | I6: Greg Bianco Jill Elbertson | J6: 609-685-7657 | K6: gbianco@assempak.com jelbertson@assempak
A7: Atlas | C7: Boxes | D7: 8 - Not Approved/ Reapproval needed | H7: - | I7: Lindsay Billet | K7: lbillet@atlascontainer.com
A8: Carter Distribution | C8: Distribution | D8: 8 - Not Approved/ Reapproval needed | H8: Cory Timmons | I8: Mark Carter | J8: 775-745-9826 | K8: mark@carterdc.com
A9: CH Robinson | C9: Freight (Ocean/International) | D9: 8 - Not Approved/ Reapproval needed | H9: Cory Timmons | I9: Marc Manna | K9: marc.Manna@chrobinson.com
A10: DWK Life Sciences | C10: Glass | D10: 8 - Not Approved/ Reapproval needed | H10: Cory Timmons
A11: Engineered Plastics | C11: Recycler (Erie, PA) | D11: 8 - Not Approved/ Reapproval needed | H11: Cory Timmons | I11: Don McMillen | J11: (814)774-2970 | K11: dm@engineeredplastics.com
A12: Freightquote | C12: Freight | D12: 8 - Not Approved/ Reapproval needed | H12: Cory Timmons | I12: Glenn Connors | K12: Glenn.Connors@freightquote.com
A13: Gerreshimer | C13: Glass | D13: 8 - Not Approved/ Reapproval needed | H13: - | I13: Joe Cortese | K13: joe.cortese@gerresheimer.com
A14: Gold Leaf | C14: Boxes | D14: 8 - Not Approved/ Reapproval needed | H14: Cory Timmons
A15: HiTech | C15: Injection molding | D15: 8 - Not Approved/ Reapproval needed | H15: Cory Timmons | I15: Rob Loranger Jr. | J15: 415-264-7269 | K15: rj@hitech-plastics.com
A16: Jeneet | C16: Reycler, FEP | D16: 8 - Not Approved/ Reapproval needed | G16: HLoeb > Jeneet Scrap Process | H16: Cory Timmons | I16: Tim Walsh | J16: 401-921-5366 | K16: tim@jeneet.com
A17: K Sidrane Inc | C17: Print | D17: 8 - Not Approved/ Reapproval needed | G17: Link | H17: Cory Timmons | I17: Zach Sidrane | J17: 631-393-6974 | K17: ZSidrane@ksidrane.com
A18: KIMAC | C18: Rework | D18: 8 - Not Approved/ Reapproval needed | H18: Rob Bullen
A19: M&R | C19: Labels | D19: 8 - Not Approved/ Reapproval needed | H19: Jess Bart | I19: Steve Brownstone | K19: Steve@mrlabel.com
A20: Macaran | C20: Labels | D20: 8 - Not Approved/ Reapproval needed | H20: Jess Bart | I20: Pat Degnan Donna Kamkar | K20: pdegnan@macaran.com dkamkar@macaran.com
A21: Milwright | C21: Injection molding | D21: 8 - Not Approved/ Reapproval needed | H21: Cory Timmons | I21: Danelle Devine Lucinda Blackburn | J21: 801-440-0581 ‪‪208-313-1533 | K21: danelle@compaxpackaging.com, lblackburn@compaxpackaging.com
A22: Northcore Industries, Inc. | C22: Cores | D22: 8 - Not Approved/ Reapproval needed | H22: Rob Bullen
A23: Pack4 | C23: Foam Insert | D23: 8 - Not Approved/ Reapproval needed | H23: - | I23: Nick Litano | K23: nlitano@pack4.com
A24: Package Development Company | C24: Thermoform | D24: 8 - Not Approved/ Reapproval needed | H24: - | I24: Rick Folbrecht | K24: r.folbrecht@pkgdev.com
A25: Packlane | C25: Boxes | D25: 8 - Not Approved/ Reapproval needed | H25: Cory Timmons | I25: TJ King | K25: tking@packlane.com
A26: Phenix Labels | C26: Labels | D26: 8 - Not Approved/ Reapproval needed | H26: Jess Bart | I26: Greg Russell | K26: grussell@phenixlabel.com
A27: Pinnacle Roller Co | C27: Finishing Rollers | D27: 8 - Not Approved/ Reapproval needed | H27: Rob Bullen | I27: Michael Brown | J27: 513-369-4830 | K27: Mike@metzgermachine.com
A28: Plate Crafters | C28: Plate | D28: 8 - Not Approved/ Reapproval needed | E28: VQ Needed | H28: Rob Bullen | I28: Paul Netwal | J28: 352-455-3020 | K28: paul@platecrafters.com
A29: Poli | C29: Thermoform | D29: 8 - Not Approved/ Reapproval needed | H29: Cory Timmons | I29: Magdalena Piniewska | J29: +48 52 352 79 40 | K29: magdalena.piniewska@poli.com.pl
A30: Polyfit | C30: Recycler, Plastic West Coast | D30: 8 - Not Approved/ Reapproval needed | G30: Link | H30: Cory Timmons | I30: Luis Gutierrez | J30: 664-406-75-77 | K30: luis@polyfit.us
A31: Printing Arts | C31: Boxes | D31: 8 - Not Approved/ Reapproval needed | H31: Cory Timmons | I31: Doug Still | K31: dstill@printarts.com
A32: Qspac | C32: Laminate | D32: 8 - Not Approved/ Reapproval needed | H32: Rob Bullen | I32: Jeff Esslair | J32: 714-213-9684 | K32: Jeffe@qspac.com
A33: Raflatac | C33: Facestock | D33: 8 - Not Approved/ Reapproval needed | H33: Rob Bullen | I33: Thomas Gray | J33: 828-290-5783 | K33: thomas.gray@upmraflatac.com
A34: SDI Packaging | C34: Tray Inserts | D34: 8 - Not Approved/ Reapproval needed | H34: Cory Timmons | I34: Joannie Leduc | K34: jleduc@sdipackaging.com
A35: Senawave | C35: Internet | D35: 8 - Not Approved/ Reapproval needed | H35: Rob Bullen | I35: Ladd Marshall | J35: 801-217-9003
A36: Shuman Plastics | C36: Recycler, Plastic East Coast | D36: 8 - Not Approved/ Reapproval needed | G36: Link | H36: Cory Timmons | I36: Dan Shuman | J36: 716-685-2121 # 103 | K36: info@shuman-plastics.com
A37: Strategic Materials | C37: Recycler, Glass East Coast | D37: 8 - Not Approved/ Reapproval needed | G37: Link | H37: Cory Timmons | I37: Dora Servidio | J37: 860-334-7263 | K37: dservidio@smi.com
A38: Strategic Materials | C38: Recycler, Glass West Coast | D38: 8 - Not Approved/ Reapproval needed | H38: Cory Timmons | I38: Alex Vega | J38: 281-507-8682 | K38: avega@smi.com
A39: Sundial / Bottle Coatings | D39: 8 - Not Approved/ Reapproval needed
A40: UPS SCS | D40: 8 - Not Approved/ Reapproval needed | I40: Daniel Plante | K40: daniel.plante@ups.com
...

Sheet Stage List
A1: Stage
A2: 1 - NDA Submitted
A3: 2 - Vendor Qualification
A4: 3 - Sampling/Pricing
A5: 4 - Contract in Draft
A6: 5 - Contract Negoiation
A7: 6 - Contract Submitted for Signature
A8: 7 - Active
A9: 8 - Not Approved/ Reapproval needed

Sheet Vendor Holiday Closure Tracking
B1: 2023 | E1: 2024 | J1: Vendor | K1: Contact(s) | L1: Email
A2: Vendor | B2: Q2 | C2: Q3 | D2: Q4 | E2: Q1 | F2: Q2 | G2: Q3 | H2: Q4 | J2: Compax | K2: Danelle Devine | L2: danelle@compaxpackaging.com
A3: Compax | B3: x+ | C3: x+ | D3: x | J3: Compax | K3: Lucinda Blackburn | L3: lblackburn@compaxpackaging.com
A4: Assempak | B4: x+ | C4: x+ | D4: x | J4: Assempak | K4: Greg Bianco | L4: gbianco@assempak.com
A5: LogisticsPlus | B5: x+ | C5: x+ | D5: x | J5: LogisticsPlus | K5: Danielle Minges | L5: danielle.minges@logisticsplus.com
A6: American Durafilm | B6: x+ | C6: x+ | J6: LogisticsPlus | K6: Calyx Support | L6: calyx@logisticsplus.com
A7: HLoeb | B7: x+ | C7: x+ | D7: x | J7: American Durafilm | K7: Jon Goodwin | L7: jgoodwin@americandurafilm.com
A8: Spectragraphics | B8: x+ | C8: x+ | J8: HLoeb | K8: Geoff Foucher | L8: gfaucher@hloeb.com
A9: Printing Arts | B9: x+ | C9: x+ | J9: HLoeb | K9: Francine Denis | L9: FDenis@hloeb.com
A10: Source One | B10: x+ | C10: x+ | J10: Spectragraphics | K10: Carol Sroor | L10: carols@spectragraphics.com
A11: UPS | B11: x | C11: x+ | J11: Spectragraphics | K11: Erik Rodriguez | L11: erikr@spectragraphics.com
A12: Fedex | J12: Printing Arts | K12: Doug Still | L12: dstill@printarts.com
A13: Propeller | C13: x+ | J13: Source One | K13: Nick Griffo | L13: ng@sourceonepackagingllc.com
A14: Vision AF | D14: x | J14: UPS | K14: Kevin (Boyd) Johnson | L14: boydjohnson@ups.com
A15: K Sidrane | J15: Fedex | K15: Carol Johnson | L15: cajohnson9@fedex.com
A16: Aspen Press | J16: Propeller | K16: Avery Christensen | L16: achristensen@propellerinc.com
A17: Inhance Technologies | J17: Vision Automated Fulfillment | K17: Tracy York | L17: tracy@visionaf.com
A18: Freightquote | B18: x+ | C18: x+ | D18: n/a | J18: K Sidrane | K18: ? | L18: ?
A19: CHR | B19: x+ | D19: n/a | J19: Aspen Press | K19: Roger Green | L19: roger@aspenpress.com
A20: Carter DC | B20: x+ | C20: n/a | J20: Inhance Technologies | K20: Chris Ridenour | L20: cridenour@inhancetechnologies.com
A21: HiTech | C21: n/a

Sheet Drams
A1: Vendor | B1: What | C1: Where | D1: Contact
A2: Compax | B2: Base/lid injection molding | C2: Salt Lake City, UT
A3: Milwright | B3: Lid injection molding | C3: CA
A4: HiTech | B4: Lid injection molding | C4: Buena Park, CA
A5: Spectragraphics | B5: Label Printing | C5: Lenexa, KS
A6: Zinga | B6: Label Printing | C6: Ventura, CA
A7: M&R | B7: Label Printing | C7: University Park, IL
A8: Phenix Labels | B8: Label Printing- Upcoming | C8: Olathe, KS
A9: W2G | B9: 3rd Party Warehouse (Funoco) | C9: Lindon, UT
A10: SDI Packaging | B10: Stick N' Grip Productioon | C10: Anjou (QC)

Sheet Tubes
A1: Vendor | B1: What | C1: Where | D1: Contact
A2: Wellpack | B2: Tube Injection Molding | C2: Jiangmen, GU 529 075 CN
A3: W2G | B3: 3rd Party Warehouse (Funoco) | C3: Lindon, UT
A4: Macaran | B4: Tube Label Printer | C4: Cohoes, NY

Sheet Extracts
A1: Vendor | B1: What | C1: Where | D1: Contact
A2: Gerreshimer | B2: Glass production | C2: Lohr, Germany
A3: Compax | B3: Base/lid injection molding | C3: Salt Lake City, UT
A4: Milwright | B4: Lid injection molding | C4: CA
A5: HiTech | B5: Lid injection molding | C5: Buena Park, CA
A6: Spectragraphics | B6: Label Printing | C6: Lenexa, KS
A7: Zinga | B7: Label Printing | C7: Ventura, CA
A8: Phenix Labels | B8: Label Printing- Upcoming | C8: Olathe, KS
A9: W2G | B9: 3rd Party Warehouse (Funoco) | C9: Lindon, UT
A10: Assempak | B10: Repacker / FEP Insertion | C10: Vineland, NJ
A11: Atlas | B11: Outerbox (250 case count) | C11: Severn, MD
A12: American Durafilm | B12: FEP Thermoform Production | C12: Holliston, MA
A13: H. Loeb Corporation | B13: FEP Die Cutting | C13: New Bedford, MA

Sheet 8th Glass
A1: Vendor | B1: What | C1: Where | D1: Contact
A2: Gerreshimer | B2: Glass production | C2: Lohr, Germany
A3: Compax | B3: Base/lid injection molding | C3: Salt Lake City, UT
A4: Milwright | B4: Lid injection molding | C4: CA
A5: Spectragraphics | B5: Label Printing | C5: Lenexa, KS
A6: Phenix Labels | B6: Label Printing- Upcoming | C6: Olathe, KS
A7: TBD | B7: Box vendor
